<?xml version="1.0" ?>
<!-- =================================================================================== -->
<!-- |    This document was autogenerated by xacro from hexa_model.xacro               | -->
<!-- |    EDITING THIS FILE BY HAND IS NOT RECOMMENDED                                 | -->
<!-- =================================================================================== -->
<sdf version="1.5">
  <world name="default">
    <include>
      <uri>model://ground_plane</uri>
    </include>
    <include>
      <uri>model://sun</uri>
    </include>
    <model name="Leptan">
      <!-- Body -->
      <link name="body">
        <inertial>
          <pose>0 0 0.0175 0 0 0</pose>
          <mass>0.1</mass>
          <inertia>
            <ixx>0.1</ixx>
            <ixy>0.0</ixy>
            <ixz>0.0</ixz>
            <iyy>0.1</iyy>
            <iyz>0.0</iyz>
            <izz>0.1</izz>
          </inertia>
        </inertial>
        <collision name="collision">
          <pose>0 0 0.17600000000000002 0 0 0</pose>
          <geometry>
            <box>
              <size>0.032 0.22 0.042</size>
            </box>
          </geometry>
        </collision>
        <visual name="visual">
          <pose>0 0.1 0.197 0 0 0</pose>
          <geometry>
            <mesh>
              <uri>model://Hexa/meshes/Body.stl</uri>
              <scale> 0.001 0.001 0.001 </scale>
            </mesh>
          </geometry>
        </visual>
      </link>
      <link name="coxa_LF">
        <inertial>
          <pose>0 0 0.0175 0 0 0</pose>
          <mass>0.1</mass>
          <inertia>
            <ixx>0.1</ixx>
            <ixy>0.0</ixy>
            <ixz>0.0</ixz>
            <iyy>0.1</iyy>
            <iyz>0.0</iyz>
            <izz>0.1</izz>
          </inertia>
        </inertial>
        <collision name="collision">
          <pose>0.125 0.114 0.18 0 1.5707963267948966 0.0</pose>
          <geometry>
            <box>
              <size>0.032 0.06 0.042</size>
            </box>
          </geometry>
        </collision>
        <visual name="visual">
          <pose>0.125 0.1325 0.18 0 1.5707963267948966 0.0</pose>
          <geometry>
            <mesh>
              <uri>model://Hexa/meshes/Coxa.stl</uri>
              <scale> 0.001 0.001 0.001 </scale>
            </mesh>
          </geometry>
        </visual>
      </link>
      <joint name="body_to_coxa_LF" type="revolute">
        <pose>0.125 0.065 0.18 0 0 0</pose>
        <child>coxa_LF</child>
        <parent>body</parent>
        <axis>
          <limit>
            <lower>-2.356194490192345</lower>
            <upper>2.356194490192345</upper>
          </limit>
          <xyz>0 0 1</xyz>
        </axis>
      </joint>
      <link name="femur_LF">
        <inertial>
          <pose>0 0 0.0175 0 0 0</pose>
          <mass>0.1</mass>
          <inertia>
            <ixx>0.1</ixx>
            <ixy>0.0</ixy>
            <ixz>0.0</ixz>
            <iyy>0.1</iyy>
            <iyz>0.0</iyz>
            <izz>0.1</izz>
          </inertia>
        </inertial>
        <collision name="collision">
          <pose>0.125 0.1825 0.18  1.5707963267948966 0 1.5707963267948966</pose>
          <geometry>
            <box>
              <size>0.024 0.025 0.048</size>
            </box>
          </geometry>
        </collision>
        <visual name="visual">
          <pose>0.101 0.1825 0.18  1.5707963267948966 0 1.5707963267948966</pose>
          <geometry>
            <mesh>
              <uri>model://Hexa/meshes/Femur.stl</uri>
              <scale> 0.001 0.001 0.001 </scale>
            </mesh>
          </geometry>
        </visual>
      </link>
      <joint name="coxa_to_femur_LF" type="revolute">
        <pose>0.125 0.1325 0.18 0 0 0</pose>
        <child>femur_LF</child>
        <parent>coxa_LF</parent>
        <axis>
          <limit>
            <lower>-2.356194490192345</lower>
            <upper>2.356194490192345</upper>
          </limit>
          <xyz>1 0 0</xyz>
        </axis>
      </joint>
      <link name="tibia_LF">
        <inertial>
          <pose>0 0 0.0175 0 0 0</pose>
          <mass>0.1</mass>
          <inertia>
            <ixx>0.1</ixx>
            <ixy>0.0</ixy>
            <ixz>0.0</ixz>
            <iyy>0.1</iyy>
            <iyz>0.0</iyz>
            <izz>0.1</izz>
          </inertia>
        </inertial>
        <collision name="collision">
          <pose>0.125 0.2325 0.18  1.5707963267948966 0 1.5707963267948966</pose>
          <geometry>
            <mesh>
              <uri>model://Hexa/meshes/TibiaCol.stl</uri>
              <scale> 0.001 0.001 0.001 </scale>
            </mesh>
          </geometry>
        </collision>
        <visual name="visual">
          <pose>0.125 0.2325 0.18  1.5707963267948966 0 1.5707963267948966</pose>
          <geometry>
            <mesh>
              <uri>model://Hexa/meshes/Tibia.stl</uri>
              <scale> 0.001 0.001 0.001 </scale>
            </mesh>
          </geometry>
        </visual>
      </link>
      <joint name="femur_to_tibia_LF" type="revolute">
        <pose>0.125 0.2325 0.18 0 0 0</pose>
        <child>tibia_LF</child>
        <parent>femur_LF</parent>
        <axis>
          <limit>
            <lower>-2.356194490192345</lower>
            <upper>2.356194490192345</upper>
          </limit>
          <xyz>1 0 0</xyz>
        </axis>
      </joint>
      <link name="coxa_LM">
        <inertial>
          <pose>0 0 0.0175 0 0 0</pose>
          <mass>0.1</mass>
          <inertia>
            <ixx>0.1</ixx>
            <ixy>0.0</ixy>
            <ixz>0.0</ixz>
            <iyy>0.1</iyy>
            <iyz>0.0</iyz>
            <izz>0.1</izz>
          </inertia>
        </inertial>
        <collision name="collision">
          <pose>0.0 0.14900000000000002 0.18 0 1.5707963267948966 0.0</pose>
          <geometry>
            <box>
              <size>0.032 0.06 0.042</size>
            </box>
          </geometry>
        </collision>
        <visual name="visual">
          <pose>0.0 0.1675 0.18 0 1.5707963267948966 0.0</pose>
          <geometry>
            <mesh>
              <uri>model://Hexa/meshes/Coxa.stl</uri>
              <scale> 0.001 0.001 0.001 </scale>
            </mesh>
          </geometry>
        </visual>
      </link>
      <joint name="body_to_coxa_LM" type="revolute">
        <pose>0.0 0.1 0.18 0 0 0</pose>
        <child>coxa_LM</child>
        <parent>body</parent>
        <axis>
          <limit>
            <lower>-2.356194490192345</lower>
            <upper>2.356194490192345</upper>
          </limit>
          <xyz>0 0 1</xyz>
        </axis>
      </joint>
      <link name="femur_LM">
        <inertial>
          <pose>0 0 0.0175 0 0 0</pose>
          <mass>0.1</mass>
          <inertia>
            <ixx>0.1</ixx>
            <ixy>0.0</ixy>
            <ixz>0.0</ixz>
            <iyy>0.1</iyy>
            <iyz>0.0</iyz>
            <izz>0.1</izz>
          </inertia>
        </inertial>
        <collision name="collision">
          <pose>0.0 0.21750000000000003 0.18  1.5707963267948966 0 1.5707963267948966</pose>
          <geometry>
            <box>
              <size>0.024 0.025 0.048</size>
            </box>
          </geometry>
        </collision>
        <visual name="visual">
          <pose>-0.024 0.21750000000000003 0.18  1.5707963267948966 0 1.5707963267948966</pose>
          <geometry>
            <mesh>
              <uri>model://Hexa/meshes/Femur.stl</uri>
              <scale> 0.001 0.001 0.001 </scale>
            </mesh>
          </geometry>
        </visual>
      </link>
      <joint name="coxa_to_femur_LM" type="revolute">
        <pose>0.0 0.1675 0.18 0 0 0</pose>
        <child>femur_LM</child>
        <parent>coxa_LM</parent>
        <axis>
          <limit>
            <lower>-2.356194490192345</lower>
            <upper>2.356194490192345</upper>
          </limit>
          <xyz>1 0 0</xyz>
        </axis>
      </joint>
      <link name="tibia_LM">
        <inertial>
          <pose>0 0 0.0175 0 0 0</pose>
          <mass>0.1</mass>
          <inertia>
            <ixx>0.1</ixx>
            <ixy>0.0</ixy>
            <ixz>0.0</ixz>
            <iyy>0.1</iyy>
            <iyz>0.0</iyz>
            <izz>0.1</izz>
          </inertia>
        </inertial>
        <collision name="collision">
          <pose>0.0 0.2675 0.18  1.5707963267948966 0 1.5707963267948966</pose>
          <geometry>
            <mesh>
              <uri>model://Hexa/meshes/TibiaCol.stl</uri>
              <scale> 0.001 0.001 0.001 </scale>
            </mesh>
          </geometry>
        </collision>
        <visual name="visual">
          <pose>0.0 0.2675 0.18  1.5707963267948966 0 1.5707963267948966</pose>
          <geometry>
            <mesh>
              <uri>model://Hexa/meshes/Tibia.stl</uri>
              <scale> 0.001 0.001 0.001 </scale>
            </mesh>
          </geometry>
        </visual>
      </link>
      <joint name="femur_to_tibia_LM" type="revolute">
        <pose>0.0 0.2675 0.18 0 0 0</pose>
        <child>tibia_LM</child>
        <parent>femur_LM</parent>
        <axis>
          <limit>
            <lower>-2.356194490192345</lower>
            <upper>2.356194490192345</upper>
          </limit>
          <xyz>1 0 0</xyz>
        </axis>
      </joint>
      <link name="coxa_LR">
        <inertial>
          <pose>0 0 0.0175 0 0 0</pose>
          <mass>0.1</mass>
          <inertia>
            <ixx>0.1</ixx>
            <ixy>0.0</ixy>
            <ixz>0.0</ixz>
            <iyy>0.1</iyy>
            <iyz>0.0</iyz>
            <izz>0.1</izz>
          </inertia>
        </inertial>
        <collision name="collision">
          <pose>-0.125 0.114 0.18 0 1.5707963267948966 0.0</pose>
          <geometry>
            <box>
              <size>0.032 0.06 0.042</size>
            </box>
          </geometry>
        </collision>
        <visual name="visual">
          <pose>-0.125 0.1325 0.18 0 1.5707963267948966 0.0</pose>
          <geometry>
            <mesh>
              <uri>model://Hexa/meshes/Coxa.stl</uri>
              <scale> 0.001 0.001 0.001 </scale>
            </mesh>
          </geometry>
        </visual>
      </link>
      <joint name="body_to_coxa_LR" type="revolute">
        <pose>-0.125 0.065 0.18 0 0 0</pose>
        <child>coxa_LR</child>
        <parent>body</parent>
        <axis>
          <limit>
            <lower>-2.356194490192345</lower>
            <upper>2.356194490192345</upper>
          </limit>
          <xyz>0 0 1</xyz>
        </axis>
      </joint>
      <link name="femur_LR">
        <inertial>
          <pose>0 0 0.0175 0 0 0</pose>
          <mass>0.1</mass>
          <inertia>
            <ixx>0.1</ixx>
            <ixy>0.0</ixy>
            <ixz>0.0</ixz>
            <iyy>0.1</iyy>
            <iyz>0.0</iyz>
            <izz>0.1</izz>
          </inertia>
        </inertial>
        <collision name="collision">
          <pose>-0.125 0.1825 0.18  1.5707963267948966 0 1.5707963267948966</pose>
          <geometry>
            <box>
              <size>0.024 0.025 0.048</size>
            </box>
          </geometry>
        </collision>
        <visual name="visual">
          <pose>-0.149 0.1825 0.18  1.5707963267948966 0 1.5707963267948966</pose>
          <geometry>
            <mesh>
              <uri>model://Hexa/meshes/Femur.stl</uri>
              <scale> 0.001 0.001 0.001 </scale>
            </mesh>
          </geometry>
        </visual>
      </link>
      <joint name="coxa_to_femur_LR" type="revolute">
        <pose>-0.125 0.1325 0.18 0 0 0</pose>
        <child>femur_LR</child>
        <parent>coxa_LR</parent>
        <axis>
          <limit>
            <lower>-2.356194490192345</lower>
            <upper>2.356194490192345</upper>
          </limit>
          <xyz>1 0 0</xyz>
        </axis>
      </joint>
      <link name="tibia_LR">
        <inertial>
          <pose>0 0 0.0175 0 0 0</pose>
          <mass>0.1</mass>
          <inertia>
            <ixx>0.1</ixx>
            <ixy>0.0</ixy>
            <ixz>0.0</ixz>
            <iyy>0.1</iyy>
            <iyz>0.0</iyz>
            <izz>0.1</izz>
          </inertia>
        </inertial>
        <collision name="collision">
          <pose>-0.125 0.2325 0.18  1.5707963267948966 0 1.5707963267948966</pose>
          <geometry>
            <mesh>
              <uri>model://Hexa/meshes/TibiaCol.stl</uri>
              <scale> 0.001 0.001 0.001 </scale>
            </mesh>
          </geometry>
        </collision>
        <visual name="visual">
          <pose>-0.125 0.2325 0.18  1.5707963267948966 0 1.5707963267948966</pose>
          <geometry>
            <mesh>
              <uri>model://Hexa/meshes/Tibia.stl</uri>
              <scale> 0.001 0.001 0.001 </scale>
            </mesh>
          </geometry>
        </visual>
      </link>
      <joint name="femur_to_tibia_LR" type="revolute">
        <pose>-0.125 0.2325 0.18 0 0 0</pose>
        <child>tibia_LR</child>
        <parent>femur_LR</parent>
        <axis>
          <limit>
            <lower>-2.356194490192345</lower>
            <upper>2.356194490192345</upper>
          </limit>
          <xyz>1 0 0</xyz>
        </axis>
      </joint>
      <link name="coxa_RF">
        <inertial>
          <pose>0 0 0.0175 0 0 0</pose>
          <mass>0.1</mass>
          <inertia>
            <ixx>0.1</ixx>
            <ixy>0.0</ixy>
            <ixz>0.0</ixz>
            <iyy>0.1</iyy>
            <iyz>0.0</iyz>
            <izz>0.1</izz>
          </inertia>
        </inertial>
        <collision name="collision">
          <pose>0.125 -0.114 0.18 0 1.5707963267948966 3.141592653589793</pose>
          <geometry>
            <box>
              <size>0.032 0.06 0.042</size>
            </box>
          </geometry>
        </collision>
        <visual name="visual">
          <pose>0.125 -0.1325 0.18 0 1.5707963267948966 3.141592653589793</pose>
          <geometry>
            <mesh>
              <uri>model://Hexa/meshes/Coxa.stl</uri>
              <scale> 0.001 0.001 0.001 </scale>
            </mesh>
          </geometry>
        </visual>
      </link>
      <joint name="body_to_coxa_RF" type="revolute">
        <pose>0.125 -0.065 0.18 0 0 0</pose>
        <child>coxa_RF</child>
        <parent>body</parent>
        <axis>
          <limit>
            <lower>-2.356194490192345</lower>
            <upper>2.356194490192345</upper>
          </limit>
          <xyz>0 0 1</xyz>
        </axis>
      </joint>
      <link name="femur_RF">
        <inertial>
          <pose>0 0 0.0175 0 0 0</pose>
          <mass>0.1</mass>
          <inertia>
            <ixx>0.1</ixx>
            <ixy>0.0</ixy>
            <ixz>0.0</ixz>
            <iyy>0.1</iyy>
            <iyz>0.0</iyz>
            <izz>0.1</izz>
          </inertia>
        </inertial>
        <collision name="collision">
          <pose>0.125 -0.1825 0.18  1.5707963267948966 0 -1.5707963267948966</pose>
          <geometry>
            <box>
              <size>0.024 0.025 0.048</size>
            </box>
          </geometry>
        </collision>
        <visual name="visual">
          <pose>0.149 -0.1825 0.18  1.5707963267948966 0 -1.5707963267948966</pose>
          <geometry>
            <mesh>
              <uri>model://Hexa/meshes/Femur.stl</uri>
              <scale> 0.001 0.001 0.001 </scale>
            </mesh>
          </geometry>
        </visual>
      </link>
      <joint name="coxa_to_femur_RF" type="revolute">
        <pose>0.125 -0.1325 0.18 0 0 0</pose>
        <child>femur_RF</child>
        <parent>coxa_RF</parent>
        <axis>
          <limit>
            <lower>-2.356194490192345</lower>
            <upper>2.356194490192345</upper>
          </limit>
          <xyz>1 0 0</xyz>
        </axis>
      </joint>
      <link name="tibia_RF">
        <inertial>
          <pose>0 0 0.0175 0 0 0</pose>
          <mass>0.1</mass>
          <inertia>
            <ixx>0.1</ixx>
            <ixy>0.0</ixy>
            <ixz>0.0</ixz>
            <iyy>0.1</iyy>
            <iyz>0.0</iyz>
            <izz>0.1</izz>
          </inertia>
        </inertial>
        <collision name="collision">
          <pose>0.125 -0.2325 0.18  1.5707963267948966 0 -1.5707963267948966</pose>
          <geometry>
            <mesh>
              <uri>model://Hexa/meshes/TibiaCol.stl</uri>
              <scale> 0.001 0.001 0.001 </scale>
            </mesh>
          </geometry>
        </collision>
        <visual name="visual">
          <pose>0.125 -0.2325 0.18  1.5707963267948966 0 -1.5707963267948966</pose>
          <geometry>
            <mesh>
              <uri>model://Hexa/meshes/Tibia.stl</uri>
              <scale> 0.001 0.001 0.001 </scale>
            </mesh>
          </geometry>
        </visual>
      </link>
      <joint name="femur_to_tibia_RF" type="revolute">
        <pose>0.125 -0.2325 0.18 0 0 0</pose>
        <child>tibia_RF</child>
        <parent>femur_RF</parent>
        <axis>
          <limit>
            <lower>-2.356194490192345</lower>
            <upper>2.356194490192345</upper>
          </limit>
          <xyz>1 0 0</xyz>
        </axis>
      </joint>
      <link name="coxa_RM">
        <inertial>
          <pose>0 0 0.0175 0 0 0</pose>
          <mass>0.1</mass>
          <inertia>
            <ixx>0.1</ixx>
            <ixy>0.0</ixy>
            <ixz>0.0</ixz>
            <iyy>0.1</iyy>
            <iyz>0.0</iyz>
            <izz>0.1</izz>
          </inertia>
        </inertial>
        <collision name="collision">
          <pose>0.0 -0.14900000000000002 0.18 0 1.5707963267948966 3.141592653589793</pose>
          <geometry>
            <box>
              <size>0.032 0.06 0.042</size>
            </box>
          </geometry>
        </collision>
        <visual name="visual">
          <pose>0.0 -0.1675 0.18 0 1.5707963267948966 3.141592653589793</pose>
          <geometry>
            <mesh>
              <uri>model://Hexa/meshes/Coxa.stl</uri>
              <scale> 0.001 0.001 0.001 </scale>
            </mesh>
          </geometry>
        </visual>
      </link>
      <joint name="body_to_coxa_RM" type="revolute">
        <pose>0.0 -0.1 0.18 0 0 0</pose>
        <child>coxa_RM</child>
        <parent>body</parent>
        <axis>
          <limit>
            <lower>-2.356194490192345</lower>
            <upper>2.356194490192345</upper>
          </limit>
          <xyz>0 0 1</xyz>
        </axis>
      </joint>
      <link name="femur_RM">
        <inertial>
          <pose>0 0 0.0175 0 0 0</pose>
          <mass>0.1</mass>
          <inertia>
            <ixx>0.1</ixx>
            <ixy>0.0</ixy>
            <ixz>0.0</ixz>
            <iyy>0.1</iyy>
            <iyz>0.0</iyz>
            <izz>0.1</izz>
          </inertia>
        </inertial>
        <collision name="collision">
          <pose>0.0 -0.21750000000000003 0.18  1.5707963267948966 0 -1.5707963267948966</pose>
          <geometry>
            <box>
              <size>0.024 0.025 0.048</size>
            </box>
          </geometry>
        </collision>
        <visual name="visual">
          <pose>0.024 -0.21750000000000003 0.18  1.5707963267948966 0 -1.5707963267948966</pose>
          <geometry>
            <mesh>
              <uri>model://Hexa/meshes/Femur.stl</uri>
              <scale> 0.001 0.001 0.001 </scale>
            </mesh>
          </geometry>
        </visual>
      </link>
      <joint name="coxa_to_femur_RM" type="revolute">
        <pose>0.0 -0.1675 0.18 0 0 0</pose>
        <child>femur_RM</child>
        <parent>coxa_RM</parent>
        <axis>
          <limit>
            <lower>-2.356194490192345</lower>
            <upper>2.356194490192345</upper>
          </limit>
          <xyz>1 0 0</xyz>
        </axis>
      </joint>
      <link name="tibia_RM">
        <inertial>
          <pose>0 0 0.0175 0 0 0</pose>
          <mass>0.1</mass>
          <inertia>
            <ixx>0.1</ixx>
            <ixy>0.0</ixy>
            <ixz>0.0</ixz>
            <iyy>0.1</iyy>
            <iyz>0.0</iyz>
            <izz>0.1</izz>
          </inertia>
        </inertial>
        <collision name="collision">
          <pose>0.0 -0.2675 0.18  1.5707963267948966 0 -1.5707963267948966</pose>
          <geometry>
            <mesh>
              <uri>model://Hexa/meshes/TibiaCol.stl</uri>
              <scale> 0.001 0.001 0.001 </scale>
            </mesh>
          </geometry>
        </collision>
        <visual name="visual">
          <pose>0.0 -0.2675 0.18  1.5707963267948966 0 -1.5707963267948966</pose>
          <geometry>
            <mesh>
              <uri>model://Hexa/meshes/Tibia.stl</uri>
              <scale> 0.001 0.001 0.001 </scale>
            </mesh>
          </geometry>
        </visual>
      </link>
      <joint name="femur_to_tibia_RM" type="revolute">
        <pose>0.0 -0.2675 0.18 0 0 0</pose>
        <child>tibia_RM</child>
        <parent>femur_RM</parent>
        <axis>
          <limit>
            <lower>-2.356194490192345</lower>
            <upper>2.356194490192345</upper>
          </limit>
          <xyz>1 0 0</xyz>
        </axis>
      </joint>
      <link name="coxa_RR">
        <inertial>
          <pose>0 0 0.0175 0 0 0</pose>
          <mass>0.1</mass>
          <inertia>
            <ixx>0.1</ixx>
            <ixy>0.0</ixy>
            <ixz>0.0</ixz>
            <iyy>0.1</iyy>
            <iyz>0.0</iyz>
            <izz>0.1</izz>
          </inertia>
        </inertial>
        <collision name="collision">
          <pose>-0.125 -0.114 0.18 0 1.5707963267948966 3.141592653589793</pose>
          <geometry>
            <box>
              <size>0.032 0.06 0.042</size>
            </box>
          </geometry>
        </collision>
        <visual name="visual">
          <pose>-0.125 -0.1325 0.18 0 1.5707963267948966 3.141592653589793</pose>
          <geometry>
            <mesh>
              <uri>model://Hexa/meshes/Coxa.stl</uri>
              <scale> 0.001 0.001 0.001 </scale>
            </mesh>
          </geometry>
        </visual>
      </link>
      <joint name="body_to_coxa_RR" type="revolute">
        <pose>-0.125 -0.065 0.18 0 0 0</pose>
        <child>coxa_RR</child>
        <parent>body</parent>
        <axis>
          <limit>
            <lower>-2.356194490192345</lower>
            <upper>2.356194490192345</upper>
          </limit>
          <xyz>0 0 1</xyz>
        </axis>
      </joint>
      <link name="femur_RR">
        <inertial>
          <pose>0 0 0.0175 0 0 0</pose>
          <mass>0.1</mass>
          <inertia>
            <ixx>0.1</ixx>
            <ixy>0.0</ixy>
            <ixz>0.0</ixz>
            <iyy>0.1</iyy>
            <iyz>0.0</iyz>
            <izz>0.1</izz>
          </inertia>
        </inertial>
        <collision name="collision">
          <pose>-0.125 -0.1825 0.18  1.5707963267948966 0 -1.5707963267948966</pose>
          <geometry>
            <box>
              <size>0.024 0.025 0.048</size>
            </box>
          </geometry>
        </collision>
        <visual name="visual">
          <pose>-0.101 -0.1825 0.18  1.5707963267948966 0 -1.5707963267948966</pose>
          <geometry>
            <mesh>
              <uri>model://Hexa/meshes/Femur.stl</uri>
              <scale> 0.001 0.001 0.001 </scale>
            </mesh>
          </geometry>
        </visual>
      </link>
      <joint name="coxa_to_femur_RR" type="revolute">
        <pose>-0.125 -0.1325 0.18 0 0 0</pose>
        <child>femur_RR</child>
        <parent>coxa_RR</parent>
        <axis>
          <limit>
            <lower>-2.356194490192345</lower>
            <upper>2.356194490192345</upper>
          </limit>
          <xyz>1 0 0</xyz>
        </axis>
      </joint>
      <link name="tibia_RR">
        <inertial>
          <pose>0 0 0.0175 0 0 0</pose>
          <mass>0.1</mass>
          <inertia>
            <ixx>0.1</ixx>
            <ixy>0.0</ixy>
            <ixz>0.0</ixz>
            <iyy>0.1</iyy>
            <iyz>0.0</iyz>
            <izz>0.1</izz>
          </inertia>
        </inertial>
        <collision name="collision">
          <pose>-0.125 -0.2325 0.18  1.5707963267948966 0 -1.5707963267948966</pose>
          <geometry>
            <mesh>
              <uri>model://Hexa/meshes/TibiaCol.stl</uri>
              <scale> 0.001 0.001 0.001 </scale>
            </mesh>
          </geometry>
        </collision>
        <visual name="visual">
          <pose>-0.125 -0.2325 0.18  1.5707963267948966 0 -1.5707963267948966</pose>
          <geometry>
            <mesh>
              <uri>model://Hexa/meshes/Tibia.stl</uri>
              <scale> 0.001 0.001 0.001 </scale>
            </mesh>
          </geometry>
        </visual>
      </link>
      <joint name="femur_to_tibia_RR" type="revolute">
        <pose>-0.125 -0.2325 0.18 0 0 0</pose>
        <child>tibia_RR</child>
        <parent>femur_RR</parent>
        <axis>
          <limit>
            <lower>-2.356194490192345</lower>
            <upper>2.356194490192345</upper>
          </limit>
          <xyz>1 0 0</xyz>
        </axis>
      </joint>
      <static>false</static>
    </model>
  </world>
</sdf>
